File: src/quickplot_example/Gd2O3_AlN_map_data.txt
#Acq. time (s)=	3
#Accumulations=	2
#Range (cm-¹)=	100...1200
#Windows=	1
#Auto scanning=	Off
#Autofocus=	Off
#SWIFT=	Off
#AutoExposure=	Off
#Spike filter=	Multiple accum.
#Delay time (s)=	0
#Binning=	1
#Readout mode=	Signal
#DeNoise=	Off
#ICS correction=	Off
#Dark correction=	Off
#Inst. Process=	Off
#Detector Gain=	Best Dynamic Range
#Detector ADC=	20 kHz
#Detector temperature (°C)=	-130.09
#Instrument=	LabRAM HR Evol
#Detector=	Synapse/Symphony II
#Objective=	x10
#Grating=	600 gr/mm
#ND Filter=	10%
#Laser (nm)=	473
#Hole=	100.021
#Range=	Visible
#StageXY=	Marzhauser
#StageZ=	Marzhauser
#Z (µm)=	135.5
#Full time(mm:ss)=	7:53
#Project=
#Sample=	HHT-REF
#Site=
#Title=	AlN_Gd2O3_indepth
#Remark=
#Date=	17.10.2024 14:22
#Acquired=	17.10.2024 14:22:32
#AxisType[0]=Intens
#AxisUnit[0]=Cnt
#AxisType[1]=Spectr
#AxisUnit[1]=1/cm
#AxisType[2]=X
#AxisUnit[2]=µm
#AxisType[3]=Y
#AxisUnit[3]=µm
		100.166	102.502	104.837	107.171	109.505	111.839	114.172	116.504	118.836	121.167	123.498	125.829	128.158	130.488	132.816	135.145	137.473	139.8	142.125	144.451	146.777	149.102	151.427	153.751	156.075	158.396	160.719	163.041	165.363	167.683	170.003	172.323	174.643	176.96	179.279	181.597	183.913	186.23	188.546	190.861	193.176	195.491	197.804	200.118	202.43	204.743	207.054	209.366	211.676	213.987	216.296	218.606	220.914	223.222	225.529	227.837	230.143	232.45	234.755	237.061	239.364	241.668	243.972	246.274	248.576	250.879	253.18	255.48	257.781	260.081	262.38	264.678	266.977	269.274	271.571	273.867	276.163	278.46	280.755	283.049	285.343	287.636	289.929	292.222	294.514	296.805	299.096	301.386	303.676	305.965	308.254	310.542	312.83	315.117	317.404	319.69	321.976	324.261	326.546	328.83	331.114	333.396	335.678	337.961	340.242	342.524	344.804	347.085	349.363	351.642	353.921	356.199	358.477	360.753	363.029	365.306	367.58	369.855	372.13	374.404	376.677	378.95	381.223	383.494	385.765	388.035	390.306	392.576	394.845	397.114	399.381	401.65	403.916	406.183	408.449	410.715	412.98	415.245	417.508	419.773	422.035	424.297	426.56	428.821	431.082	433.343	435.603	437.863	440.121	442.38	444.637	446.896	449.152	451.408	453.665	455.92	458.175	460.429	462.683	464.937	467.19	469.442	471.694	473.945	476.195	478.446	480.695	482.946	485.195	487.443	489.691	491.938	494.185	496.431	498.677	500.922	503.167	505.411	507.655	509.898	512.141	514.382	516.624	518.866	521.107	523.347	525.587	527.826	530.064	532.302	534.541	536.778	539.015	541.25	543.486	545.722	547.957	550.19	552.424	554.658	556.89	559.123	561.355	563.585	565.816	568.046	570.276	572.506	574.734	576.963	579.19	581.418	583.644	585.87	588.096	590.321	592.546	594.771	596.994	599.218	601.44	603.662	605.884	608.105	610.326	612.546	614.766	616.986	619.204	621.422	623.641	625.858	628.074	630.29	632.507	634.722	636.936	639.15	641.364	643.578	645.791	648.003	650.215	652.426	654.637	656.847	659.057	661.266	663.476	665.684	667.892	670.1	672.307	674.513	676.719	678.924	681.128	683.333	685.537	687.74	689.943	692.146	694.348	696.55	698.751	700.951	703.151	705.351	707.55	709.749	711.946	714.144	716.341	718.538	720.733	722.929	725.125	727.32	729.513	731.707	733.9	736.093	738.286	740.477	742.668	744.858	747.049	749.24	751.428	753.618	755.805	757.994	760.18	762.368	764.554	766.739	768.925	771.11	773.295	775.478	777.662	779.845	782.027	784.21	786.391	788.572	790.752	792.933	795.112	797.291	799.47	801.648	803.826	806.003	808.179	810.356	812.532	814.707	816.881	819.055	821.229	823.402	825.575	827.749	829.92	832.092	834.263	836.433	838.603	840.772	842.941	845.11	847.278	849.446	851.612	853.778	855.944	858.11	860.276	862.44	864.605	866.769	868.931	871.094	873.256	875.418	877.579	879.74	881.901	884.061	886.219	888.379	890.538	892.695	894.853	897.01	899.166	901.322	903.479	905.633	907.788	909.942	912.096	914.248	916.402	918.553	920.706	922.857	925.008	927.158	929.308	931.457	933.607	935.755	937.903	940.051	942.197	944.344	946.491	948.636	950.781	952.926	955.07	957.213	959.356	961.5	963.642	965.784	967.925	970.067	972.207	974.347	976.486	978.625	980.764	982.901	985.039	987.176	989.314	991.45	993.586	995.721	997.856	999.99	1002.12	1004.26	1006.39	1008.52	1010.65	1012.79	1014.92	1017.05	1019.18	1021.31	1023.44	1025.56	1027.69	1029.82	1031.95	1034.08	1036.2	1038.33	1040.45	1042.58	1044.7	1046.83	1048.95	1051.07	1053.2	1055.32	1057.44	1059.56	1061.68	1063.8	1065.92	1068.04	1070.16	1072.28	1074.4	1076.51	1078.63	1080.75	1082.86	1084.98	1087.09	1089.21	1091.32	1093.44	1095.55	1097.66	1099.78	1101.89	1104	1106.11	1108.22	1110.33	1112.44	1114.55	1116.66	1118.77	1120.88	1122.98	1125.09	1127.2	1129.3	1131.41	1133.51	1135.62	1137.72	1139.82	1141.93	1144.03	1146.13	1148.23	1150.34	1152.44	1154.54	1156.64	1158.74	1160.84	1162.94	1165.03	1167.13	1169.23	1171.32	1173.42	1175.52	1177.61	1179.71	1181.8	1183.9	1185.99	1188.08	1190.18	1192.27	1194.36	1196.45	1198.54
-209.871	-129.827	53	52	53	52	61	58	50	67	70	67	62	53	65	62	59	64	66	61	63	69	65	62	71	61	73	67	55	66	59	56	68	63	59	68	64	63	72	74	63	65	63	64	72	71	66	68	68	66	75	55	68	67	51	71	73	62	72	70	74	71	75	73	75	92	135	103	73	63	73	69	57	62	55	59	70	71	58	58	63	53	61	63	53	63	57	68	57	56	65	54	67	56	62	61	58	62	55	58	61	64	61	61	61	58	63	56	54	62	67	69	65	98	127	179	176	128	100	85	63	56	58	59	57	57	58	55	57	50	54	42	62	57	43	56	50	59	57	43	52	52	59	56	48	39	55	45	48	47	49	62	54	57	62	51	50	41	51	57	53	56	56	43	51	47	50	52	49	45	54	51	54	55	52	54	47	56	61	61	46	61	62	56	42	57	61	66	59	58	55	58	64	68	57	63	50	64	55	64	63	51	61	54	66	68	67	72	77	71	68	77	71	75	80	78	83	78	83	94	108	108	138	168	272	405	614	685	599	506	449	367	341	298	280	251	240	238	235	230	236	254	273	314	401	668	1221	1822	1544	843	499	425	487	593	459	303	203	140	129	108	100	89	92	91	82	82	81	78	68	79	70	76	75	69	75	73	68	66	70	80	61	63	63	67	70	72	72	68	66	63	62	70	67	78	71	70	81	59	74	66	77	76	68	79	66	74	62	73	70	85	69	68	75	82	82	68	72	72	81	65	76	82	81	78	76	71	90	71	83	88	78	76	79	84	77	79	74	95	86	86	96	79	91	78	72	74	77	84	94	94	98	103	108	107	129	137	143	143	150	166	159	170	167	175	190	160	132	111	90	71	67	74	81	69	72	74	73	57	70	60	65	52	80	61	62	61	78	61	64	52	64	67	70	73	66	64	69	73	57	73	64	67	62	75	65	61	84	68	74	85	70	63	67	71	67	65	77	64	69	81	73	58	71	71	71	73	81	75	70	81	85	70	68	77	80	74	71	73	78	84	73	63	86	95	94	73	71	75	81	84	80	79	70	77	84	78	74	81	68	83	78	68	76	79	91	88	75	80	87	78	79	74	79	71	76	75	78	83	80	73	75	81	77	79	76	70	81	89	71	71	81	85	75	68	79	77	78	71	78	75
-209.871	-18.4453	40	36	26	45	44	45	57	153	371	310	109	83	66	55	57	91	79	62	67	101	105	55	42	46	31	50	44	39	46	53	62	54	56	53	53	50	47	44	44	43	64	52	63	62	46	57	44	41	48	52	43	46	48	49	48	57	54	51	50	57	56	55	54	74	102	91	70	64	61	71	60	62	63	56	59	60	57	67	58	68	75	66	80	84	91	107	128	117	111	112	121	156	213	278	263	174	132	103	111	106	118	125	136	150	143	165	202	262	307	439	657	1143	2267	3707	3841	2600	1454	856	554	446	367	342	273	216	188	143	167	148	142	141	144	167	147	154	152	139	148	140	129	113	119	124	136	131	147	145	146	186	217	278	341	334	283	223	167	139	136	116	96	84	70	91	99	87	87	83	79	87	70	81	80	82	86	85	87	96	78	86	87	71	78	80	82	85	82	72	80	72	85	89	78	89	102	89	103	108	110	131	136	138	142	149	177	189	242	272	274	240	217	183	157	149	136	134	144	129	118	121	121	132	149	152	195	284	419	477	460	379	319	311	263	237	240	237	205	211	198	198	207	197	217	250	291	443	756	1167	1105	666	404	327	320	438	366	266	190	155	154	121	132	114	116	111	113	103	95	97	106	108	102	102	119	95	101	110	106	97	95	100	101	90	89	85	94	92	81	90	97	85	81	93	86	74	98	83	79	68	85	87	92	89	86	87	86	94	95	99	90	90	94	95	96	91	95	89	98	98	90	93	97	96	97	83	95	98	94	92	99	89	84	91	112	100	81	101	102	94	97	98	93	93	98	99	106	104	105	113	97	115	104	99	112	132	121	133	142	131	142	150	138	144	155	166	170	151	124	124	100	108	95	81	98	98	95	80	93	94	86	104	100	92	87	84	80	84	87	88	96	86	87	83	82	85	104	84	93	95	101	93	100	96	105	98	98	95	107	104	106	98	103	97	100	95	104	95	105	102	107	107	109	108	105	103	113	97	117	107	110	113	110	104	118	110	103	97	123	125	106	120	104	111	122	122	117	121	113	110	110	129	110	124	115	112	121	127	118	134	128	133	120	123	122	131	125	138	114	121	112	113	121	108	122	115	116	105	120	114	114	108	112	111	116	114	107	125	102	107	109	103	114	114	104	106	121	120	105	113	90	98
-209.871	92.9359	65	50	53	56	71	67	97	222	584	587	199	125	105	75	74	112	116	90	104	162	182	97	76	63	52	62	58	53	67	58	75	76	59	59	53	64	55	61	54	50	60	65	83	79	63	47	56	49	64	55	59	64	50	47	56	56	50	56	48	47	60	68	65	67	67	70	64	78	69	69	67	71	70	71	87	76	73	79	78	97	102	94	96	134	131	144	199	203	189	170	175	209	295	425	422	293	209	163	165	157	175	170	202	218	242	275	315	356	466	666	1029	1782	3482	5923	6570	4532	2602	1509	956	709	587	529	433	339	305	255	239	223	229	202	199	230	249	213	205	208	211	198	179	182	171	156	180	184	192	202	227	257	325	461	523	503	448	309	277	210	172	156	135	120	114	119	123	111	119	123	115	112	115	109	112	85	91	107	111	107	105	98	95	90	88	98	97	90	96	102	94	104	95	107	103	115	118	120	123	136	134	162	183	191	210	222	245	299	337	390	406	351	313	267	237	208	178	177	151	158	130	135	133	124	133	127	121	118	125	98	115	117	101	122	121	132	128	109	121	118	124	135	133	130	123	121	122	135	123	110	118	121	114	106	116	127	130	121	127	123	131	139	136	135	123	131	119	121	118	122	114	117	104	114	130	124	120	126	113	108	106	98	101	98	107	95	98	110	95	88	92	94	93	86	93	94	91	99	97	95	90	95	91	94	92	91	91	103	93	98	103	98	99	102	91	104	91	93	91	92	94	93	92	92	88	89	91	97	91	79	92	84	75	86	94	93	83	89	88	84	90	87	90	81	92	86	80	88	93	83	91	87	95	98	88	87	78	88	89	93	97	92	86	90	88	88	86	82	77	78	75	98	79	81	78	77	81	79	91	87	80	81	91	80	93	91	91	90	98	78	94	93	78	91	86	84	84	88	95	83	92	86	83	88	105	84	100	93	98	85	92	97	81	81	88	89	89	82	89	92	90	93	75	91	99	98	90	90	94	99	91	90	108	103	95	111	104	102	108	102	116	111	115	112	111	111	117	119	120	106	112	111	126	116	126	130	119	118	118	126	118	121	120	115	128	119	117	110	119	104	119	112	100	98	96	110	106	107	97	111	100	101	102	95	99	98	107	96	103	92	94	97	102	97	85	98	102	91	97	94	103	89
-209.871	204.317	69	58	56	70	62	62	98	220	620	600	190	153	101	90	78	120	135	102	101	158	199	97	73	66	70	74	69	69	65	75	77	85	57	70	66	73	68	58	57	64	68	79	96	77	68	80	75	69	67	65	68	63	66	63	76	68	52	68	76	70	70	75	70	82	75	80	85	74	77	90	90	87	92	95	90	85	106	94	110	102	100	111	115	134	150	171	220	202	191	187	182	238	335	468	454	317	220	190	175	176	180	196	220	237	248	276	348	391	492	725	1043	1828	3567	6178	7018	4889	2775	1619	1020	776	657	567	457	366	305	266	249	248	236	227	244	258	268	238	220	218	221	227	197	194	181	180	195	187	213	207	245	288	368	488	564	611	488	380	286	238	190	156	154	151	145	129	148	128	120	117	122	122	116	117	121	115	112	113	107	119	108	122	117	103	105	107	109	106	116	99	117	121	101	104	117	124	129	129	131	151	173	175	191	200	240	227	269	326	378	412	427	409	352	309	264	228	204	192	169	183	148	162	133	144	148	134	132	114	134	144	126	136	135	133	154	132	142	148	126	140	135	132	146	131	140	139	128	129	119	134	125	119	134	132	130	145	146	145	148	144	159	160	151	154	145	147	148	138	144	136	134	140	141	147	147	146	148	141	149	122	122	121	118	130	114	125	114	124	118	125	118	116	119	114	122	117	113	114	108	118	111	109	121	103	107	115	107	119	118	119	122	106	114	106	110	109	107	123	110	106	117	114	106	114	111	115	130	120	116	116	106	114	101	103	105	121	119	113	107	105	113	118	110	106	116	110	124	127	117	106	110	114	122	120	110	111	118	120	106	116	106	117	115	115	116	114	107	103	114	99	108	119	115	107	104	105	103	117	106	107	107	113	117	120	108	126	124	111	110	113	110	120	114	122	120	112	119	113	116	115	126	126	111	119	107	120	114	123	120	124	110	121	122	117	111	122	126	121	135	130	119	136	133	110	118	132	122	133	137	126	128	119	128	137	143	134	139	133	136	136	137	155	143	128	138	147	136	144	167	144	164	150	158	148	156	154	158	155	167	171	157	159	152	164	149	153	140	139	138	142	141	138	135	148	147	131	138	129	151	135	137	142	129	132	139	136	132	148	127	120	144	137	131	144	131	132	127	127	123	134	120	139
-131.133	-129.827	11	11	16	10	27	26	24	38	53	41	30	27	21	26	24	31	25	31	28	29	31	32	29	34	29	26	32	30	20	29	25	32	31	32	31	28	35	30	37	33	31	34	39	36	41	35	32	39	31	37	38	42	41	40	46	33	39	39	44	41	44	38	57	117	171	92	54	39	47	47	47	37	40	37	37	45	44	51	35	36	41	50	42	46	38	46	54	40	43	49	59	55	64	66	54	60	53	46	56	47	47	51	52	49	57	57	70	68	78	82	103	176	292	451	458	290	202	136	87	86	76	67	70	51	58	52	53	65	53	54	59	62	53	51	54	54	52	62	56	55	59	55	54	54	50	60	61	66	72	82	81	85	78	71	54	57	56	52	61	56	57	47	52	54	63	57	64	61	53	61	45	57	63	66	67	53	56	66	72	74	79	71	79	58	81	71	74	76	82	72	78	81	75	76	81	71	79	84	85	74	88	80	90	82	101	89	115	97	107	96	113	103	110	108	119	128	131	138	156	177	204	276	453	797	1291	1398	1161	977	783	674	607	499	471	416	408	377	395	359	396	404	444	500	670	1169	2505	3921	3114	1508	809	691	912	1159	863	446	264	215	166	147	138	123	126	121	95	99	96	83	103	85	86	82	92	89	91	91	93	93	88	82	85	98	81	99	93	77	74	91	89	90	92	87	84	87	86	85	92	94	92	92	93	78	102	79	85	90	81	85	78	99	94	97	84	93	101	102	99	85	92	99	97	93	102	102	100	105	92	92	90	93	95	100	113	97	107	107	104	98	108	114	116	103	109	118	94	103	110	105	116	116	127	134	154	186	196	195	230	244	235	272	280	302	304	340	305	274	217	179	125	120	121	100	111	100	97	106	105	91	88	88	92	94	92	85	88	102	89	87	87	101	109	93	103	90	92	104	90	99	104	103	103	85	89	105	95	103	111	116	102	107	100	90	111	105	102	116	112	109	119	106	104	103	118	113	124	111	108	97	105	111	113	108	114	114	110	116	114	114	117	110	123	98	109	114	102	114	101	120	103	122	118	115	115	99	117	107	109	119	118	117	111	115	113	115	129	110	123	122	117	104	120	117	114	117	119	108	109	113	103	100	115	108	111	114	130	123	115	105	103	117	116	104	105	109	122	105	110	102	113	112
-131.133	-18.4453	53	53	36	54	57	61	73	151	345	254	107	88	77	62	62	88	86	74	70	108	101	78	71	66	71	59	66	63	68	75	65	69	75	77	69	61	54	74	68	65	70	74	83	83	67	62	67	70	69	73	69	70	86	77	72	77	67	76	79	71	71	83	99	148	194	130	93	89	93	69	77	89	81	85	89	78	92	79	94	87	85	101	96	100	110	126	137	141	120	114	138	144	203	261	236	183	142	130	119	116	140	130	144	162	155	176	201	231	295	386	548	979	1926	2972	2902	1895	1108	659	450	353	323	286	229	189	189	164	155	139	151	129	166	165	149	156	137	142	159	136	137	136	119	126	129	135	147	151	153	178	225	259	294	311	249	190	165	147	147	130	116	108	109	109	125	102	120	116	122	119	125	116	117	111	117	128	119	113	114	115	113	126	111	124	127	117	122	125	123	121	113	125	123	129	137	139	138	142	161	150	161	158	180	186	200	235	253	280	267	230	227	215	201	192	183	187	167	184	196	193	193	214	267	329	463	783	1222	1273	1094	910	791	683	601	530	509	466	450	428	431	416	408	441	482	528	690	1124	2339	3670	2984	1527	843	708	887	1112	860	509	321	262	223	208	185	189	156	161	157	172	153	138	137	154	133	150	142	142	152	140	134	142	134	122	128	127	142	138	133	123	124	127	129	130	126	123	122	116	124	119	124	118	134	117	127	136	134	124	116	111	123	112	125	124	121	122	123	113	140	141	131	124	127	124	131	127	140	120	122	126	152	135	134	134	131	129	135	139	130	137	142	136	135	164	140	129	144	139	143	138	133	144	150	149	154	166	203	209	225	246	253	278	284	289	299	323	334	359	351	291	255	205	151	160	152	137	130	122	127	128	126	141	124	130	122	122	123	120	116	129	131	122	126	125	123	126	124	136	126	129	125	129	121	120	138	130	127	148	115	130	136	134	117	137	135	129	143	138	136	142	143	125	135	135	140	126	142	139	131	153	144	148	146	126	136	141	142	135	134	134	137	149	135	169	149	144	145	156	159	148	147	143	159	164	149	154	150	158	154	163	140	137	158	142	154	143	132	135	146	154	141	153	136	148	155	142	149	144	144	138	144	134	132	146	137	139	148	142	132	131	147	139	141	149	150	138	142	151	139	132	130	132	129	130
-131.133	92.9359	64	55	56	51	53	69	95	224	628	583	174	126	95	64	80	118	114	93	99	154	161	85	64	57	67	57	57	53	55	72	74	62	63	59	46	61	54	63	75	52	65	73	76	66	63	61	63	54	46	46	49	53	42	49	60	57	69	48	57	64	56	70	62	75	69	77	61	67	68	69	75	74	76	70	84	86	81	88	92	92	93	101	103	113	124	163	211	195	179	171	173	217	316	450	440	296	203	181	163	157	170	189	200	211	236	282	318	382	479	685	1067	1832	3611	6122	6721	4630	2636	1510	944	703	609	534	432	336	287	264	244	214	218	222	241	249	243	217	184	208	214	202	175	175	170	166	170	167	193	209	222	260	347	460	522	527	414	353	270	213	194	160	148	136	132	133	107	118	114	108	108	94	114	106	110	122	107	97	104	89	100	89	93	92	91	93	89	87	95	95	97	104	98	91	105	91	110	112	129	136	131	148	181	185	188	222	252	318	358	395	396	364	324	274	212	198	174	164	168	154	142	127	118	119	117	127	126	123	111	102	123	120	110	118	120	126	115	125	118	112	121	113	114	119	120	111	119	124	128	104	115	113	113	107	118	106	125	126	117	133	138	123	116	138	111	120	123	122	106	113	111	110	112	108	127	133	118	125	114	117	106	108	100	100	96	93	93	103	94	93	93	91	96	82	97	102	94	79	97	91	83	86	104	87	79	97	100	95	93	91	85	98	94	96	88	95	84	89	86	82	85	87	79	99	89	94	99	93	84	85	87	90	83	82	90	91	97	88	80	101	78	73	88	84	90	88	85	90	88	90	99	93	95	85	80	94	89	85	88	84	92	92	97	91	100	82	82	96	89	91	77	94	92	97	88	101	85	82	91	84	86	107	101	95	87	93	94	91	88	91	89	104	90	79	86	92	92	91	99	78	89	96	94	97	98	101	92	93	95	110	92	93	101	92	101	100	104	91	107	88	108	97	100	86	90	90	82	102	93	107	92	98	97	101	95	99	108	115	100	105	110	106	111	110	118	121	119	116	118	114	123	123	117	118	112	126	123	128	132	117	123	125	120	128	119	126	104	114	120	107	112	120	112	109	102	115	117	105	103	118	111	88	99	108	93	113	99	110	94	99	100	95	101	100	96	97	99	99	90	102	91	103
-131.133	204.317	86	69	70	70	70	71	111	255	678	623	210	159	114	97	95	129	129	104	112	174	201	97	78	71	83	68	80	80	73	85	93	69	66	88	75	75	81	75	76	82	85	94	112	89	94	78	56	79	64	65	75	65	75	77	77	70	84	82	76	85	80	74	90	87	82	96	92	87	94	82	92	98	85	95	98	98	107	108	115	109	111	117	124	132	162	195	219	221	204	197	207	246	360	477	484	329	233	192	180	189	190	207	235	250	258	317	332	422	524	688	1128	1951	3716	6443	7126	4943	2798	1626	1006	759	670	607	448	377	325	314	259	255	232	244	247	263	271	233	217	239	251	230	201	193	203	194	200	204	200	224	254	287	383	475	591	615	489	389	308	229	211	186	178	154	152	145	130	130	145	136	130	131	136	136	126	141	104	129	129	116	130	127	116	111	114	120	115	118	112	124	125	125	130	121	135	141	122	134	149	163	179	191	211	218	243	249	297	331	391	430	447	426	345	317	275	224	204	192	181	184	173	176	165	162	162	144	149	152	151	143	139	153	150	162	153	149	159	170	155	148	165	162	155	156	163	165	149	152	140	142	156	132	150	140	155	167	162	154	167	161	167	169	174	165	165	150	153	157	150	143	147	143	140	170	150	140	161	168	161	141	127	124	123	133	137	130	123	126	135	131	134	132	127	128	118	125	130	113	118	124	132	127	123	128	123	127	115	108	131	127	131	119	119	117	116	109	126	125	130	121	118	117	117	128	123	126	129	133	126	107	120	116	119	117	116	118	110	120	121	124	122	117	110	125	126	108	133	124	120	129	116	120	130	126	124	125	121	125	122	126	118	128	129	122	121	133	112	123	127	122	126	126	130	123	117	127	117	123	118	132	134	120	124	124	131	128	121	132	120	132	125	126	129	125	118	136	134	145	119	120	144	119	130	124	138	124	138	129	132	140	125	136	126	122	128	141	124	125	131	127	142	124	139	119	130	138	138	135	138	143	140	139	150	143	128	149	138	150	144	142	156	148	154	166	158	156	172	159	166	163	161	167	147	170	170	161	173	176	163	174	174	162	156	168	166	164	167	149	170	137	153	147	148	144	151	137	157	140	151	140	152	147	135	144	144	154	138	145	149	140	128	154	129	154	137	148	147	134	154	141	136	144
-52.395	-129.827	38	33	38	35	45	31	44	46	56	49	44	49	45	42	40	41	42	49	59	56	59	58	61	53	55	46	58	54	56	56	58	57	52	61	56	55	64	67	61	66	58	63	66	51	74	62	61	67	69	56	74	72	64	73	74	61	78	63	80	69	73	71	77	101	140	111	78	75	60	73	73	66	72	69	69	65	66	77	70	63	63	59	65	59	69	79	71	71	68	68	72	67	78	83	75	84	73	68	77	73	78	73	73	75	68	84	77	69	91	94	112	128	204	273	269	189	150	109	102	93	87	81	92	79	74	76	73	78	84	76	90	77	86	73	84	81	78	79	69	83	78	76	72	87	74	78	86	82	89	93	96	97	94	93	83	83	89	85	84	92	83	86	83	87	87	81	76	84	86	87	81	95	98	97	95	98	97	83	94	95	90	99	91	102	98	101	100	101	104	97	114	108	95	92	101	107	105	115	98	110	117	104	102	116	124	116	126	120	122	130	122	128	135	118	134	130	148	156	178	180	196	242	325	508	778	844	768	621	547	480	413	391	371	351	336	317	312	304	312	331	362	418	531	826	1487	2166	1886	1055	647	544	596	743	616	356	261	220	195	201	175	166	154	152	149	145	139	124	147	126	131	150	129	150	133	136	132	129	135	142	129	120	138	137	138	139	143	139	138	138	131	135	134	136	142	139	126	138	145	135	138	140	127	144	143	152	140	147	161	148	149	149	137	136	173	149	146	137	153	156	154	174	148	166	154	160	157	155	162	147	150	168	162	157	169	159	188	164	163	170	183	172	166	164	166	188	171	169	166	184	170	184	200	208	228	237	250	247	260	274	262	286	291	276	286	256	242	198	190	177	175	170	168	179	165	168	164	161	167	165	169	161	169	157	172	166	167	159	165	154	161	154	169	177	171	172	172	152	178	165	175	171	176	171	171	188	184	185	182	178	182	176	173	175	168	169	183	182	190	189	183	181	189	192	195	187	199	188	198	193	184	187	191	196	207	196	183	202	199	212	198	193	216	211	197	207	206	209	199	212	201	210	219	193	198	202	190	205	204	221	210	207	225	209	193	196	211	213	221	222	206	222	216	201	207	196	219	212	223	213	215	205	203	210	194	213	207	215	220	225	226	218	222	223	242	214	219	217	206	226
-52.395	-18.4453	47	40	42	41	45	48	60	119	251	184	86	64	63	62	57	70	65	55	63	83	81	64	49	51	53	53	52	59	57	51	62	61	56	64	60	57	59	63	55	56	55	68	57	62	61	59	63	67	50	65	59	57	64	60	69	61	64	63	69	57	65	68	75	109	180	122	80	76	69	69	75	83	66	64	62	62	64	75	73	65	73	71	73	83	93	90	115	110	103	97	100	112	165	196	175	139	110	101	107	103	103	107	123	119	136	129	162	166	210	288	444	777	1468	2258	2246	1451	871	542	358	300	263	245	190	160	136	143	133	118	121	126	130	134	129	126	103	105	119	116	104	99	102	111	104	104	106	125	126	134	167	220	230	232	180	151	142	117	111	103	101	99	88	107	92	105	89	98	90	83	102	108	90	98	94	92	83	91	92	90	84	111	103	99	96	102	109	97	91	105	108	98	101	104	112	110	122	109	120	115	135	132	131	141	162	177	214	224	218	191	167	175	156	154	164	149	148	143	156	160	166	205	213	252	418	644	1043	1153	1015	849	724	606	554	492	450	430	396	380	380	353	365	400	394	474	602	954	1897	3092	2799	1414	789	625	758	1012	833	469	293	231	199	169	165	169	140	148	135	147	127	141	123	118	122	118	123	114	127	126	113	109	119	109	119	117	114	119	111	121	109	108	116	88	123	111	106	119	119	93	106	114	107	110	95	110	113	119	105	112	117	117	107	115	120	115	107	110	114	118	123	110	116	120	120	111	115	121	116	126	110	117	104	137	119	131	119	120	123	117	134	105	131	127	118	110	124	127	128	143	131	127	122	140	143	157	159	196	187	224	232	248	221	256	274	280	292	306	302	287	221	182	155	139	120	129	113	108	120	107	115	101	105	125	116	109	110	98	116	114	105	101	106	110	119	121	114	113	125	121	107	110	119	116	113	109	114	133	124	115	122	125	124	115	116	115	114	122	119	115	120	117	122	124	121	121	131	129	125	124	125	137	128	133	125	138	147	116	133	132	143	142	129	139	136	149	138	141	132	137	134	128	139	153	139	133	132	151	147	138	144	133	142	135	146	121	137	142	145	137	141	147	130	135	137	131	135	119	139	133	142	131	130	125	117	134	138	119	136	134	122	132	138	133	115	129	136	134	136	138	132	134	126	127
-52.395	92.9359	84	53	57	61	71	80	108	250	668	613	205	148	100	90	104	136	140	95	108	189	206	99	85	77	70	71	69	73	71	74	74	71	90	74	80	74	75	73	71	70	73	87	93	78	84	67	63	76	79	60	71	64	57	66	62	59	72	67	77	75	79	78	78	82	90	83	83	83	82	91	84	91	98	95	88	96	110	103	107	117	112	123	121	123	157	183	224	221	198	195	206	248	356	494	467	335	231	190	184	186	201	216	234	252	264	314	349	426	538	730	1150	1991	3980	6677	7390	5018	2833	1655	1027	792	635	598	474	391	314	292	271	245	240	236	255	265	276	244	229	220	236	221	195	180	183	186	211	192	211	225	266	304	377	521	600	597	494	369	313	233	214	185	164	151	159	142	131	138	134	136	132	128	124	125	128	120	129	131	124	124	110	107	109	111	114	127	99	113	123	124	107	117	123	129	120	132	129	135	125	154	170	196	191	208	231	239	277	324	394	454	459	440	363	288	250	241	216	198	196	180	171	172	162	152	158	145	139	142	149	133	140	150	141	148	137	144	136	152	146	160	144	155	154	145	147	148	143	144	144	127	131	136	142	147	127	143	142	142	145	159	151	158	161	151	158	149	157	140	140	140	135	146	147	160	147	157	162	147	144	146	125	118	129	139	118	117	112	136	125	129	107	127	123	120	111	118	110	109	103	102	106	103	105	114	109	112	106	111	112	113	129	107	116	121	113	124	88	123	112	120	106	113	119	109	111	113	112	111	122	104	114	112	114	116	108	113	115	102	102	116	102	111	113	111	115	123	125	105	115	111	111	129	121	111	114	99	94	106	101	110	107	115	119	117	116	130	121	120	107	118	107	105	101	107	113	108	124	117	122	108	101	122	106	114	112	111	110	115	106	106	110	114	121	109	111	97	127	96	104	104	108	114	110	121	120	119	113	126	128	112	120	128	112	116	119	126	116	123	122	112	113	113	115	110	105	129	118	136	114	120	130	130	120	143	131	126	126	134	140	153	136	134	146	131	141	160	135	148	147	145	141	143	133	141	144	135	153	152	159	151	155	150	151	151	131	144	139	152	136	135	133	146	130	133	143	118	126	137	144	141	130	125	136	127	132	133	142	129	129	109	117	122	131	132	116	122	119	130	117	124	126	113
-52.395	204.317	96	62	69	76	82	86	110	260	691	628	208	155	110	98	104	147	149	121	126	184	208	115	94	87	79	79	83	82	80	91	83	84	74	87	83	91	73	90	84	79	84	93	101	118	90	78	79	80	69	87	89	73	84	77	81	85	80	79	83	94	80	92	102	87	89	102	111	103	90	100	114	96	108	101	101	107	105	109	116	118	132	125	138	141	153	191	238	241	209	203	204	257	350	503	510	334	252	210	204	203	206	244	242	265	289	322	365	443	551	740	1180	1996	3930	6747	7400	5144	2948	1640	1079	760	703	593	500	402	348	302	301	261	241	247	275	300	285	249	260	256	251	252	219	212	199	215	196	215	232	252	264	330	399	489	627	615	505	416	301	263	235	194	174	171	166	151	149	155	148	147	147	136	138	130	138	146	138	128	143	133	124	125	124	139	136	126	132	132	129	132	124	136	156	134	137	153	147	155	186	165	180	208	214	233	251	280	318	372	421	478	501	435	369	322	281	269	247	215	194	205	186	190	173	181	174	162	157	168	162	153	160	170	157	169	165	169	168	159	154	154	160	165	170	177	163	162	163	164	153	151	165	156	169	172	154	159	179	172	169	179	178	181	166	179	170	173	171	167	170	176	157	163	171	159	172	187	165	182	157	161	165	157	153	164	138	148	142	137	141	159	152	155	153	137	145	129	129	147	149	135	127	143	131	132	142	151	122	145	143	144	143	145	149	147	142	144	140	150	134	136	135	137	121	139	149	154	140	134	144	134	137	143	148	136	139	133	131	128	150	131	144	143	136	140	154	134	140	143	133	148	139	154	132	144	145	126	135	133	144	139	138	148	134	160	149	149	132	152	135	138	146	145	139	138	134	135	133	142	148	147	139	134	143	138	144	147	140	158	147	147	143	150	145	151	138	152	141	141	135	142	147	155	148	159	148	147	145	152	154	161	149	154	148	169	165	143	157	151	153	143	156	142	142	155	153	150	159	164	165	168	156	148	157	173	158	169	168	168	161	167	169	162	179	168	191	181	165	166	192	187	170	200	192	174	194	192	201	179	192	191	195	193	182	176	182	192	177	179	189	195	184	183	185	176	178	178	181	165	184	171	179	160	160	159	176	180	171	160	158	149	179	162	165	159	180	156	174	149	159	166	174	176
26.3429	-129.827	14	18	22	27	27	24	26	40	44	45	34	28	26	25	23	26	29	34	40	32	45	27	34	26	37	27	39	35	41	36	23	41	40	37	32	40	37	31	37	47	40	44	39	40	36	38	47	41	42	42	48	48	35	45	42	44	44	39	47	47	44	52	60	86	126	74	47	49	54	44	54	48	47	47	48	33	49	26	46	38	44	50	41	43	52	37	42	34	43	41	44	46	63	48	56	60	38	52	55	55	40	47	51	53	50	45	52	71	74	69	97	133	206	332	314	231	141	101	83	66	66	59	56	55	44	46	50	39	48	43	49	34	50	43	45	43	48	42	50	51	42	42	50	40	53	39	50	43	57	51	62	61	70	46	53	48	50	43	48	40	56	41	57	56	50	49	40	50	40	37	57	47	49	53	55	48	52	49	63	56	55	57	52	55	64	52	59	62	56	64	62	59	53	58	63	58	58	68	58	62	60	69	74	74	73	69	81	74	82	75	80	74	76	91	79	93	99	106	107	121	147	189	271	451	696	733	662	560	482	411	379	330	304	294	257	265	265	241	247	281	314	361	480	758	1332	2034	1734	995	575	491	539	648	511	308	214	159	137	121	105	108	87	91	90	82	89	81	79	68	82	71	69	83	67	65	67	81	75	68	69	74	78	73	67	69	76	64	75	71	62	72	69	75	74	73	72	65	74	76	80	74	76	78	80	74	82	74	75	70	87	75	82	84	83	72	76	90	76	75	84	79	81	77	76	83	81	92	83	87	87	75	88	80	104	98	90	92	83	96	106	97	87	81	91	96	99	89	94	105	104	92	106	127	141	142	155	150	175	176	191	202	194	210	205	162	149	115	107	96	91	90	65	66	82	80	69	78	82	64	67	78	87	77	78	78	73	77	67	66	79	68	79	62	66	78	66	73	75	80	81	79	78	86	76	79	82	81	86	88	91	82	72	83	87	85	87	87	87	80	81	88	83	77	88	77	87	82	88	95	93	85	86	81	84	82	100	93	93	93	82	88	88	96	83	105	99	87	95	83	97	94	94	96	73	104	95	110	96	88	108	83	78	97	83	100	87	87	91	98	76	95	86	88	95	91	85	88	90	90	98	97	89	75	97	88	99	85	82	85	87	100	99	87	90	89	85	90	101	91
26.3429	-18.4453	27	21	25	20	29	32	33	45	114	68	39	41	36	37	32	41	40	28	40	53	44	47	32	42	44	38	39	36	41	46	50	38	43	44	58	37	44	45	57	54	59	57	51	49	45	46	61	56	58	52	54	51	52	50	59	46	55	51	48	55	65	53	69	123	165	102	58	55	58	59	58	57	55	54	60	60	67	60	59	52	61	57	53	53	70	75	87	64	65	58	70	85	93	103	87	89	65	66	65	60	63	75	73	80	76	93	86	97	117	146	198	324	588	892	834	544	329	192	163	129	130	109	96	93	91	79	84	72	84	79	81	71	79	72	73	86	75	85	78	65	68	79	75	75	74	78	80	74	99	97	120	119	110	91	89	83	76	82	65	62	70	78	86	74	65	57	70	74	74	65	74	73	70	82	75	71	78	81	79	77	77	85	82	81	80	79	87	75	79	76	84	83	86	94	90	98	78	101	97	90	100	108	115	114	127	123	141	122	121	109	124	113	118	129	118	118	135	141	137	168	208	267	420	697	1003	1022	882	728	656	554	482	446	416	383	340	355	351	335	358	363	416	457	624	1080	2149	2827	2146	1168	682	632	781	880	674	391	265	200	165	165	140	137	126	113	101	108	126	112	115	105	114	105	110	92	110	118	101	91	84	103	105	91	102	96	106	97	101	94	92	89	103	104	103	97	93	87	93	110	99	99	104	95	106	99	95	101	96	97	102	97	92	95	110	97	103	90	95	101	97	96	108	104	113	98	108	109	107	107	112	110	106	109	108	111	107	114	128	113	121	119	126	113	108	110	117	110	117	122	123	130	125	146	159	175	184	217	218	215	237	242	273	263	278	287	277	234	177	163	148	121	110	113	101	103	113	99	105	102	101	94	100	104	119	103	96	112	116	110	97	101	112	102	107	96	114	102	103	109	95	90	117	120	103	113	106	116	113	104	103	109	111	121	115	108	123	106	110	117	123	115	116	121	129	116	115	121	113	112	128	125	126	118	125	125	135	117	133	119	131	130	114	124	123	118	116	129	118	130	117	113	136	129	120	139	140	131	126	125	134	125	126	115	118	130	133	133	143	125	131	129	130	129	123	127	118	128	135	113	130	113	131	125	126	118	131	114	120	119	122	127	128	119	115	114	119	121	123	138	123	115
26.3429	92.9359	79	63	69	62	70	89	104	246	674	577	174	139	104	94	103	138	119	118	114	179	186	108	84	81	88	87	86	76	79	101	82	80	76	91	76	91	75	70	74	72	78	88	92	85	82	75	75	68	70	81	69	79	68	75	81	58	80	77	71	73	81	73	93	89	84	93	85	82	90	105	99	89	95	98	108	97	112	114	115	115	113	133	117	142	163	171	220	220	200	197	196	222	345	467	463	303	232	188	186	179	189	205	230	258	265	292	334	418	530	714	1088	1902	3699	6317	6963	4694	2649	1534	954	725	659	567	450	385	361	348	256	242	236	218	257	257	273	246	250	240	238	235	192	204	193	188	191	197	213	228	254	288	377	479	567	569	488	366	312	223	218	197	175	174	141	148	142	154	133	129	127	122	134	128	126	123	112	128	125	127	120	109	114	120	113	116	116	125	122	117	124	123	130	135	125	148	139	145	161	168	196	189	206	220	225	255	281	314	402	445	437	410	347	315	263	226	216	181	197	187	164	179	154	169	168	146	157	165	142	147	142	151	159	153	156	137	156	141	159	161	157	162	163	156	155	153	151	148	140	141	143	151	143	145	171	156	159	165	158	172	171	164	162	170	161	160	150	140	156	151	163	148	155	153	148	154	168	150	149	155	137	128	134	140	140	123	141	126	140	138	131	127	134	139	134	127	147	117	124	128	124	130	131	118	135	134	128	127	141	120	136	136	127	130	127	125	126	139	129	148	142	125	122	131	114	130	125	123	132	132	117	126	119	119	114	127	123	138	125	135	132	125	128	121	128	125	116	123	128	133	123	144	117	125	128	141	126	122	127	119	133	141	117	116	131	134	123	124	120	124	111	123	126	124	123	137	120	132	127	120	133	130	128	136	136	126	131	139	126	134	129	132	129	131	121	136	139	137	123	133	142	136	127	140	139	137	134	133	129	136	140	147	133	132	152	127	147	137	140	146	133	128	143	143	131	140	135	141	130	137	147	159	139	138	133	143	153	147	163	142	159	150	163	167	167	170	167	171	154	161	157	174	170	167	182	176	180	168	163	182	181	185	173	177	182	166	165	161	165	159	159	160	162	151	153	163	159	159	153	172	140	166	156	165	161	141	163	164	147	154	169	143	138	136	154	133	145	140	151	134	145	158
26.3429	204.317	103	96	90	94	107	109	131	327	786	711	250	184	141	122	133	181	180	143	156	229	243	157	125	107	105	105	110	107	110	118	120	98	109	118	109	109	111	110	106	105	113	103	124	113	120	105	103	103	98	97	107	99	102	99	102	102	102	113	100	99	114	103	114	118	124	122	119	109	124	118	128	121	132	124	139	129	142	141	141	145	152	157	164	185	194	231	285	263	258	226	244	322	447	567	567	392	278	254	225	229	231	267	306	322	321	378	423	490	635	859	1343	2281	4449	7549	8185	5672	3226	1842	1163	853	763	699	566	470	399	363	316	307	299	297	296	352	305	300	291	297	292	288	265	246	238	238	237	250	264	289	337	363	456	561	694	684	611	472	364	292	283	236	209	187	206	180	186	192	178	182	174	173	179	171	167	169	165	164	166	171	151	159	158	166	154	168	169	159	181	154	181	166	178	171	182	184	186	191	211	203	228	247	278	278	284	293	348	398	467	538	553	515	455	363	346	298	281	271	236	239	224	236	200	216	222	209	214	196	207	202	203	185	191	203	193	202	194	189	200	208	201	214	211	209	204	199	203	200	194	196	185	208	208	215	203	201	204	206	212	220	222	234	235	231	228	214	219	220	213	222	196	188	206	210	194	212	223	217	199	200	184	186	195	176	171	171	183	166	179	187	173	164	171	182	174	174	171	166	166	192	174	175	165	183	172	179	166	170	164	167	173	171	183	168	180	186	184	192	179	180	171	170	169	167	175	155	169	190	186	178	173	173	173	180	171	172	173	163	160	170	183	175	182	174	171	167	177	181	167	168	164	165	169	154	174	175	189	168	173	168	176	175	167	176	183	178	176	190	175	163	160	173	183	166	171	179	160	168	178	181	180	177	167	183	191	174	183	175	159	177	191	180	188	197	186	181	178	186	188	170	186	173	175	181	179	180	193	182	189	187	187	190	170	188	192	198	188	184	168	189	180	194	183	179	186	181	191	195	202	190	192	194	198	184	182	218	209	199	203	210	200	220	204	222	221	208	222	222	226	218	216	226	218	218	230	247	230	216	232	249	244	239	234	231	222	227	235	233	211	212	214	211	211	234	199	205	209	203	221	210	207	210	230	203	204	202	192	200	210	203	207	197	209	197	196	192	197	210	212	190	196	204
105.081	-129.827	34	26	39	38	43	35	41	74	106	81	53	50	44	45	48	53	44	54	63	54	68	47	63	50	56	49	58	54	57	66	62	68	63	69	66	68	71	66	64	72	69	83	73	67	85	70	81	83	76	82	87	85	81	86	85	71	86	83	81	73	91	91	95	131	168	120	87	86	75	85	79	82	83	86	82	75	85	86	81	70	76	75	76	85	88	81	90	85	77	85	91	96	110	109	111	103	97	83	84	84	88	91	82	92	95	108	109	115	122	165	210	308	541	793	718	518	315	219	171	154	133	109	105	97	104	95	96	97	82	82	95	97	78	92	87	90	82	79	83	84	84	90	89	87	80	82	96	104	111	115	127	124	118	107	87	83	88	78	85	81	80	60	85	91	86	84	74	83	87	84	94	80	86	86	90	94	82	90	90	105	97	101	100	86	101	102	102	93	101	95	107	86	93	97	105	105	99	118	113	103	113	121	118	125	147	130	136	133	123	122	122	137	125	131	128	141	139	135	149	175	208	249	335	576	819	887	800	678	602	515	472	416	382	364	324	342	333	329	361	367	387	442	601	929	1663	2409	2030	1116	695	597	681	781	623	388	271	220	189	176	151	139	145	126	156	128	120	126	118	118	114	121	107	125	123	116	121	122	100	108	99	103	96	117	114	102	116	122	110	115	117	106	106	99	103	98	121	117	100	112	120	110	115	115	119	114	112	109	118	106	116	121	106	121	116	126	118	125	121	134	125	135	120	140	125	134	124	115	128	114	131	131	120	129	133	129	130	120	124	121	138	115	133	140	139	125	125	142	129	131	135	152	151	179	175	201	200	211	240	227	260	251	267	275	275	245	201	169	146	123	138	124	116	108	112	120	99	108	116	99	107	110	114	101	118	106	109	112	107	116	94	98	114	104	108	105	114	115	121	111	112	107	123	119	109	107	117	130	122	113	124	114	120	118	131	115	140	117	118	117	114	128	127	116	122	133	119	123	120	125	126	114	129	110	121	119	128	141	123	125	136	125	130	127	143	138	128	122	132	131	117	122	122	129	129	121	135	120	114	130	124	122	133	126	137	139	132	122	130	129	120	128	132	139	122	132	121	132	120	128	129	133	123	125	133	119	126	125	130	118	122	129	117	126	118	119	114	117	117	117
105.081	-18.4453	15	11	31	28	22	31	26	46	84	59	32	30	26	31	28	37	31	32	32	42	33	32	34	30	37	40	32	37	39	33	33	35	35	39	29	40	44	37	41	39	42	42	48	41	40	46	35	54	42	40	45	55	38	52	43	53	44	49	53	53	46	59	69	107	158	104	52	50	51	51	50	48	51	45	44	56	54	56	49	57	51	45	59	50	60	62	62	51	62	56	58	59	71	88	89	77	60	69	55	65	53	62	70	65	68	67	86	86	93	129	184	289	526	806	754	501	320	220	148	125	114	102	79	67	66	65	67	59	70	60	72	72	57	62	70	70	74	59	61	62	65	60	65	71	52	65	58	77	80	85	105	107	98	84	68	67	76	66	70	72	57	64	50	61	53	81	60	55	67	63	65	67	72	70	75	66	70	72	79	72	80	67	75	73	81	82	71	82	79	88	80	76	81	90	79	91	88	96	86	94	100	93	102	107	112	119	115	121	121	118	116	131	112	127	121	123	135	139	155	169	203	278	384	683	1043	1125	982	821	694	606	518	485	440	408	382	352	366	366	379	389	432	490	627	1092	2070	3048	2630	1402	807	633	798	954	760	450	272	215	175	163	138	137	123	107	118	106	104	102	96	105	95	99	88	94	100	97	102	92	98	95	100	83	81	90	88	87	81	93	80	91	80	101	84	98	91	89	94	84	87	87	79	86	88	94	95	80	86	85	81	96	94	88	93	86	97	96	88	89	98	95	94	99	101	100	90	100	83	103	97	100	96	91	103	94	87	109	104	111	95	101	97	110	98	106	102	111	110	112	107	104	128	129	143	151	180	197	201	222	229	237	255	259	280	287	284	242	200	155	142	113	118	105	110	90	96	92	89	96	96	75	89	94	97	86	97	98	87	97	102	91	94	92	101	81	95	90	97	90	95	89	103	95	81	95	96	99	97	92	100	99	93	102	106	108	100	99	105	93	84	101	100	88	103	97	97	102	104	95	105	114	98	102	95	105	110	116	103	104	100	107	110	110	107	115	114	115	100	100	108	93	104	109	105	110	118	117	104	109	102	109	113	103	114	105	125	107	107	109	106	108	105	113	110	113	111	109	107	98	111	105	102	102	105	98	100	109	100	92	93	95	101	103	99	98	101	98	95	91	88	96
105.081	92.9359	101	81	83	84	90	99	134	275	692	612	215	148	131	110	104	160	180	117	140	198	219	115	97	92	100	101	84	98	91	101	97	103	97	99	88	97	80	100	80	87	97	96	108	107	98	85	86	82	94	77	85	80	88	85	93	85	90	103	92	81	89	107	105	113	105	100	106	116	111	108	130	107	114	121	117	138	134	118	134	124	140	143	160	162	165	210	244	240	224	193	226	267	377	524	494	327	249	224	205	204	210	232	260	271	309	334	376	430	570	746	1132	1978	3822	6466	7211	4910	2802	1612	1024	752	685	605	477	395	372	300	298	269	266	249	272	306	272	263	237	269	261	254	216	213	194	215	219	215	235	258	271	317	390	522	637	612	505	412	337	258	237	202	189	180	188	173	155	147	149	158	163	171	159	151	151	151	143	148	165	142	146	142	139	152	139	141	142	147	155	150	148	160	154	155	156	155	169	173	176	193	196	232	232	231	261	280	307	358	441	484	487	448	398	343	288	282	237	232	211	213	202	205	197	196	197	193	178	163	167	181	170	194	186	176	187	177	185	189	192	185	194	192	182	192	192	194	183	164	176	172	191	174	181	183	194	172	184	201	203	202	192	202	203	211	199	183	201	195	187	174	192	178	182	181	174	210	193	195	194	176	176	180	170	179	172	155	160	149	170	158	157	170	145	160	160	151	151	152	160	157	166	165	161	160	159	161	164	154	157	157	160	154	165	150	172	166	172	157	153	160	160	153	176	166	166	155	145	161	148	159	163	164	167	152	148	167	156	157	145	153	176	162	153	161	159	168	165	170	160	169	151	157	157	172	149	149	156	165	154	169	162	169	158	173	170	158	162	162	140	145	160	163	183	161	157	159	161	176	170	163	175	161	171	144	160	169	174	164	165	172	145	173	164	155	166	169	172	163	167	165	167	164	159	165	181	167	186	178	176	178	177	155	174	178	166	170	181	165	171	185	176	167	183	188	178	174	177	174	177	193	196	178	182	180	178	172	178	187	189	182	171	204	211	200	190	201	212	202	212	197	203	203	218	220	234	195	210	211	218	234	222	210	215	218	215	208	221	222	209	199	204	202	202	204	191	202	203	186	192	198	191	177	199	186	182	196	186	206	191	204	186	180	195	178	196	194	182	196	197	187	191	175
105.081	204.317	93	62	78	74	84	94	119	291	667	608	223	142	113	98	112	150	160	107	122	188	209	112	96	94	73	81	86	87	77	94	90	85	93	84	79	86	69	85	75	85	84	94	117	104	93	88	75	75	77	77	77	83	74	84	91	78	93	84	86	78	93	93	91	100	97	89	104	99	114	96	103	93	98	117	104	102	99	121	123	120	138	123	148	152	170	203	240	244	210	206	212	245	363	499	518	340	273	206	195	208	193	219	239	278	310	318	362	429	585	740	1170	2022	3991	6768	7273	5038	2858	1653	1026	792	647	610	511	381	334	282	268	274	268	242	271	284	278	254	243	269	242	241	228	200	189	198	206	208	233	241	265	312	415	509	610	623	526	389	310	261	233	202	181	186	171	145	158	154	149	150	142	136	145	136	136	135	126	134	128	123	137	122	125	129	125	126	131	107	119	132	116	141	137	139	164	158	158	162	172	173	187	204	215	233	254	289	306	341	405	469	475	429	380	323	290	263	250	198	203	206	194	188	173	178	167	167	158	168	156	149	175	196	160	164	176	166	172	178	158	162	178	165	177	163	172	178	154	160	168	161	165	155	164	165	166	185	178	165	178	177	182	180	174	186	175	184	173	158	180	165	170	180	162	169	175	172	181	170	167	163	144	165	175	156	148	146	140	151	141	137	148	135	137	127	154	145	146	143	141	133	135	138	140	138	128	131	147	144	138	150	145	145	129	134	136	155	135	143	140	139	131	140	130	135	156	135	145	134	144	132	131	141	132	146	131	140	130	137	140	148	142	133	135	131	142	142	141	151	142	142	143	150	138	143	147	136	131	143	127	133	146	147	136	137	140	135	139	125	134	130	136	131	132	135	131	148	129	128	141	165	130	154	139	145	135	133	129	123	150	141	138	141	146	147	143	155	145	150	141	146	150	153	138	148	143	154	152	155	156	152	154	148	151	143	146	150	153	154	143	137	167	149	139	144	166	154	158	148	172	149	166	170	145	157	166	151	153	167	174	177	179	165	176	172	172	165	181	184	180	184	172	185	174	194	186	186	188	187	200	183	206	194	207	180	173	173	198	181	187	166	167	157	168	175	167	181	169	178	171	156	158	166	160	158	171	174	174	164	165	166	168	176	169	159	170	153	149	160	161	160	169	169
183.819	-129.827	42	39	44	48	42	37	39	55	68	56	55	54	58	54	49	48	53	46	65	61	57	48	53	47	58	53	54	45	58	60	59	47	56	57	58	66	61	53	55	52	59	57	70	62	60	46	60	57	63	52	61	65	55	68	60	62	67	58	73	67	60	63	72	102	164	99	62	61	62	69	59	59	64	63	61	57	60	55	65	66	57	64	74	60	55	62	71	65	67	69	56	65	64	62	65	59	57	56	55	58	62	55	69	64	64	65	67	67	64	80	88	108	166	233	214	177	115	92	72	76	83	73	62	66	69	61	59	63	61	68	66	63	58	69	53	70	63	57	44	50	55	57	49	64	52	62	58	58	61	60	63	61	65	66	61	58	58	67	63	59	55	55	44	62	59	67	55	62	68	63	62	59	70	74	72	69	70	67	80	70	74	82	70	71	72	74	72	71	68	73	79	66	67	77	84	70	79	76	75	78	77	81	85	80	93	85	86	99	94	85	105	97	104	99	110	99	124	119	128	166	188	239	355	586	867	937	841	700	582	492	461	399	378	333	318	322	322	299	324	331	352	428	555	916	1787	2669	2124	1116	659	592	689	807	633	365	252	191	161	119	126	125	100	108	105	91	96	101	107	87	98	89	86	90	78	86	87	93	89	84	79	82	84	85	82	82	85	88	92	85	90	83	86	88	86	92	80	86	102	81	79	89	92	87	85	78	100	104	90	81	88	90	92	108	91	98	95	103	93	98	97	109	98	108	101	102	91	79	104	102	102	93	103	107	93	106	98	107	101	111	102	106	104	112	98	100	94	112	115	106	127	128	151	153	177	182	185	191	199	207	214	222	248	248	236	214	184	153	132	114	108	101	101	104	95	90	81	94	96	81	100	93	90	88	93	92	84	90	91	95	83	99	69	90	87	85	87	82	92	83	80	91	96	85	90	90	97	96	103	91	92	89	88	96	89	96	98	106	88	98	96	96	88	95	93	97	104	99	101	85	98	93	102	105	113	116	107	100	97	100	105	112	98	95	106	111	115	95	106	106	110	102	101	99	113	92	105	114	111	112	101	109	102	111	107	101	110	102	93	110	107	108	119	108	99	108	106	100	110	107	101	100	109	109	108	116	91	102	98	105	104	94	102	102	98	85	100	97	100	96
183.819	-18.4453	48	42	34	41	50	37	52	101	199	145	71	69	54	47	53	60	65	70	69	80	78	60	52	66	61	54	62	57	63	60	65	57	59	52	69	67	70	75	62	65	72	57	73	91	62	76	70	60	64	75	74	78	75	71	71	78	67	67	62	85	81	76	81	150	193	142	97	82	91	83	84	82	76	81	87	76	70	76	76	79	76	88	82	89	98	103	111	112	95	105	102	110	140	168	150	114	108	91	100	105	94	101	112	106	107	121	132	161	176	229	335	566	1038	1610	1573	998	591	386	265	217	200	183	165	132	121	108	126	108	113	107	106	112	110	117	105	115	103	104	97	100	102	112	100	99	112	123	116	130	158	182	184	188	178	153	135	112	111	106	105	106	96	96	100	91	95	92	98	95	110	87	93	102	114	108	101	105	113	108	123	110	112	105	118	113	102	126	107	117	105	116	107	111	114	108	117	122	131	124	151	141	147	147	160	173	174	204	211	192	177	168	169	163	160	169	164	167	164	177	192	206	245	307	461	756	1208	1298	1102	944	795	674	630	567	508	461	445	424	426	390	434	445	511	561	748	1218	2380	3545	2954	1584	904	761	907	1132	881	518	348	272	238	211	183	184	157	162	144	150	142	145	149	141	136	141	141	140	132	138	129	125	128	132	127	125	131	124	127	135	136	115	128	105	147	135	130	119	136	122	120	117	120	146	119	121	135	130	120	132	126	142	128	135	123	124	126	126	119	134	132	132	134	131	151	131	129	138	128	136	131	123	138	153	128	134	136	129	156	141	142	143	141	156	140	139	156	136	146	143	158	143	161	160	169	186	174	199	231	260	269	284	283	307	308	325	352	347	334	317	251	220	174	171	163	155	149	127	135	127	137	134	123	132	135	126	135	133	125	131	135	132	142	142	131	130	118	121	129	134	147	120	124	147	136	139	142	140	150	135	154	135	149	150	140	128	136	149	146	153	157	153	141	153	153	142	141	136	154	141	156	149	148	154	145	139	151	156	154	162	148	163	150	151	168	158	171	151	162	152	150	163	147	159	160	165	156	164	150	155	167	162	151	175	185	175	173	160	150	158	175	167	175	162	162	154	163	163	156	156	156	155	150	161	156	169	158	156	162	164	159	169	167	153	160	160	161	155	147	140	146	159	140	147
183.819	92.9359	97	70	67	70	81	85	110	261	714	608	191	143	112	91	107	148	145	110	128	193	197	115	80	83	76	79	70	76	88	86	92	85	84	86	77	84	73	71	90	73	90	87	94	96	93	86	70	73	71	73	82	75	70	72	72	89	81	82	85	86	90	87	89	93	94	94	98	94	111	104	105	107	104	115	117	111	110	111	120	123	128	136	147	134	158	203	241	236	216	204	219	263	382	517	507	346	240	200	187	204	213	214	235	270	278	326	386	450	568	760	1169	2034	3999	6866	7494	5134	2868	1645	1025	784	669	599	482	390	355	290	285	276	263	253	276	286	263	263	232	222	274	232	227	200	187	207	206	218	221	251	271	315	404	510	600	593	524	392	327	257	228	206	172	172	162	152	156	159	145	146	138	142	138	128	131	153	127	132	128	114	140	120	125	126	135	116	131	115	118	129	133	129	142	131	134	133	152	149	165	175	192	202	209	211	241	283	300	351	419	483	465	437	375	323	279	253	239	211	209	198	189	179	162	161	165	163	165	166	163	163	168	156	140	153	169	155	171	159	171	172	171	175	158	175	164	154	161	149	161	155	161	139	160	163	165	156	161	178	181	187	177	173	182	186	184	181	174	157	168	177	149	160	161	155	168	175	161	156	166	138	147	158	147	150	144	141	135	139	129	153	143	132	138	144	135	141	141	137	131	121	137	134	141	138	123	126	146	123	137	151	138	138	151	146	150	149	130	143	133	132	139	130	131	129	141	137	139	136	135	137	146	141	130	139	144	145	130	128	127	132	147	132	143	126	134	127	133	140	138	143	127	131	123	140	147	133	145	146	142	131	152	140	139	134	142	137	157	149	132	144	112	145	155	141	135	142	140	129	146	138	137	140	145	144	139	144	142	146	142	144	127	136	153	143	133	153	135	151	156	145	153	148	131	154	138	165	137	142	156	153	160	163	143	154	155	158	143	142	149	166	140	144	145	146	142	148	145	147	154	147	148	144	146	166	171	149	160	147	163	168	158	169	164	157	157	187	180	163	175	179	173	193	189	175	182	181	197	184	182	199	186	197	184	184	186	199	194	175	184	172	180	186	185	174	176	174	152	164	151	162	160	166	183	173	161	163	149	162	153	172	168	162	154	159	160	154	168	155	161	158	164	156
183.819	204.317	100	79	84	71	98	99	133	296	763	650	235	149	132	112	122	162	163	137	129	227	252	125	104	103	91	82	85	97	99	96	102	101	107	88	100	93	89	96	91	95	99	114	99	119	94	107	98	101	99	88	97	93	90	91	95	96	97	107	102	103	109	91	111	108	99	111	110	121	115	125	126	132	141	120	132	139	119	147	139	144	150	152	166	175	186	221	270	271	250	239	246	295	399	574	544	372	263	242	221	217	229	250	275	278	311	354	398	472	594	803	1252	2169	4291	7257	7970	5326	3047	1747	1106	831	751	660	528	427	384	362	313	303	283	286	307	318	307	283	264	293	285	277	242	225	226	212	237	248	248	272	292	347	429	523	659	662	560	437	338	278	242	234	213	196	189	189	164	168	169	170	163	150	169	156	158	154	160	154	145	155	150	143	156	160	149	164	147	168	147	147	145	150	165	159	185	177	195	195	194	205	221	239	244	260	281	303	347	399	447	528	529	496	414	359	323	294	266	249	230	231	218	211	212	191	198	194	182	199	190	176	206	183	201	192	186	190	172	199	188	202	192	195	212	192	183	189	206	195	184	178	175	179	188	203	195	218	188	208	196	203	210	225	219	205	198	190	206	213	198	196	211	199	201	190	204	193	193	205	180	185	192	167	189	175	174	195	158	188	162	179	171	173	166	159	170	165	166	168	157	162	166	161	166	142	173	166	169	173	161	164	159	168	172	157	159	151	163	168	169	182	179	165	176	161	154	161	166	161	152	148	159	180	155	155	170	178	164	158	171	155	158	167	169	163	170	175	142	167	156	160	169	182	154	168	169	159	171	171	172	167	167	167	163	166	164	171	169	162	179	155	167	180	169	167	169	179	165	151	171	173	168	170	177	159	168	179	179	156	168	167	161	172	183	173	180	168	181	170	178	163	176	198	166	186	166	181	178	176	181	178	181	171	190	176	184	171	183	186	170	187	170	189	189	171	174	178	192	194	185	189	188	203	194	179	184	189	189	179	192	200	200	183	211	195	206	209	198	212	211	223	213	221	212	242	224	218	209	219	233	228	226	212	224	214	226	222	219	206	214	205	222	199	187	210	205	207	190	200	208	212	204	194	209	188	199	206	204	200	203	179	205	189	187	182	198	191	184	205	191	197	203	179